Workbook

Sheet Finacial Anaylsis
B1: Financial Statement Analysis
B2: Financial Modelling Course
C4: 2022A | D4: 2023A | E4: 2024A | F4: 2025A
A6: # | B6: INCOME STATEMENT | C6: 2022A | D6: 2023A | E6: 2024A | F6: 2025A
B7: Revenue from operations | C7: 575890 | D7: 680850 | E7: 798094 | F7: 860685
B8: Other Income | C8: 14806 | D8: 22896 | E8: 20458 | F8: 25616
B9: TOTAL | C9: 590696 | D9: 703746 | E9: 818552 | F9: 886301
B10: Cost of Goods Sold | C10: 387060 | D10: 467422 | E10: 549861 | F10: 602639
B11: Employee Cost | C11: 20003 | D11: 23603 | E11: 28634 | F11: 32850
B12: Other Expenses | C12: 80542 | D12: 87280 | E12: 99956 | F12: 116385
B13: TOTAL | C13: 487605 | D13: 578305 | E13: 678451 | F13: 751874
B14: EBITDA | C14: 88285 | D14: 102545 | E14: 119643 | F14: 108811
B15: Depreciation & Amortization | C15: 28218 | D15: 26039 | E15: 27598 | F15: 30208
B16: EBIT | C16: 60067 | D16: 76506 | E16: 92045 | F16: 78603
B17: Interest | C17: 817 | D17: 894 | E17: 3458 | F17: 759
B18: Profit Before Taxes | C18: 74056 | D18: 98508 | E18: 109045 | F18: 103460
... B20: Profit for the Year | C20: 53181 | D20: 72346 | E20: 76183 | F20: 73728
A22: # | B22: BALANCE SHEET | C22: 2022A | D22: 2023A | E22: 2024A | F22: 2025A
B23: SOURCES OF FUNDS
B24: Shareholder Funds | C24: 306304 | D24: 370905 | E24: 425755 | F24: 471097
B25: Share Capital | C25: 1510 | D25: 1510 | E25: 1510 | F25: 1510
B26: Reserves & Surplus | C26: 304650 | D26: 369241 | E26: 424084 | F26: 469411
B27: Minority Interest | C27: 144 | D27: 154 | E27: 161 | F27: 176
B28: Long Term Liabilities
B29: Loans | C29: 0 | D29: 0 | E29: 100 | F29: 80
B30: Other Long Term Liabilities | C30: 8075 | D30: 11055 | E30: 15859 | F30: 20371
B31: Long Term Provisions | C31: 148 | D31: 219 | E31: 265 | F31: 395
B32: Deferred Tax Liabilities | C32: 2287 | D32: 5058 | E32: 6020 | F32: 6139
B33: Current Liabilities
B34: Tax Liabilities | C34: 7956 | D34: 8036 | E34: 8541 | F34: 6729
B35: Short Term Borrowings | C35: 774 | D35: 4836 | E35: 1108 | F35: 1496
B36: Trade Payables | C36: 74089 | D36: 83692 | E36: 104993 | F36: 96377
B37: Other Current Liabilities | C37: 11650 | D37: 18278 | E37: 20896 | F37: 16329
B38: Short Term Provisions | C38: 3994 | D38: 4498 | E38: 5609 | F38: 6254
B39: Other Finance Liabilities | C39: 11978 | D39: 13028 | E39: 13338 | F39: 14420
B40: TOTAL | C40: 427255 | D40: 519605 | E40: 602484 | F40: 639687
B41: APPLICATION OF FUNDS
B42: Long Term Assets
B43: Tangible Assets | C43: 121827 | D43: 129377 | E43: 130771 | F43: 149862
B44: Intangible Assets | C44: 3469 | D44: 3730 | E44: 3117 | F44: 4511
...

Sheet Vertical Anaylsis
B2: Vertical Analysis | C2: 2022A | D2: 2023A | E2: 2024A | F2: 2025A
B4: Revenue from operations | C4: ='Finacial Anaylsis'!C7/'Finacial Anaylsis'!C$7 -> 1 | D4: ='Finacial Anaylsis'!D7/'Finacial Anaylsis'!D$7 -> 1 | E4: ='Finacial Anaylsis'!E7/'Finacial Anaylsis'!E$7 -> 1 | F4: ='Finacial Anaylsis'!F7/'Finacial Anaylsis'!F$7 -> 1
B5: Other Income | C5: ='Finacial Anaylsis'!C8/'Finacial Anaylsis'!C$7 -> 0.025709771 | D5: ='Finacial Anaylsis'!D8/'Finacial Anaylsis'!D$7 -> 0.033628553 | E5: ='Finacial Anaylsis'!E8/'Finacial Anaylsis'!E$7 -> 0.025633572 | F5: ='Finacial Anaylsis'!F8/'Finacial Anaylsis'!F$7 -> 0.02976234
B6: TOTAL | C6: ='Finacial Anaylsis'!C9/'Finacial Anaylsis'!C$7 -> 1.0257098 | D6: ='Finacial Anaylsis'!D9/'Finacial Anaylsis'!D$7 -> 1.0336286 | E6: ='Finacial Anaylsis'!E9/'Finacial Anaylsis'!E$7 -> 1.0256336 | F6: ='Finacial Anaylsis'!F9/'Finacial Anaylsis'!F$7 -> 1.0297623
B7: Raw Materials | C7: ='Finacial Anaylsis'!C10/'Finacial Anaylsis'!C$7 -> 0.67210752 | D7: ='Finacial Anaylsis'!D10/'Finacial Anaylsis'!D$7 -> 0.68652714 | E7: ='Finacial Anaylsis'!E10/'Finacial Anaylsis'!E$7 -> 0.68896772 | F7: ='Finacial Anaylsis'!F10/'Finacial Anaylsis'!F$7 -> 0.70018532
B8: Employee Cost | C8: ='Finacial Anaylsis'!C11/'Finacial Anaylsis'!C$7 -> 0.034734064 | D8: ='Finacial Anaylsis'!D11/'Finacial Anaylsis'!D$7 -> 0.03466696 | E8: ='Finacial Anaylsis'!E11/'Finacial Anaylsis'!E$7 -> 0.035877979 | F8: ='Finacial Anaylsis'!F11/'Finacial Anaylsis'!F$7 -> 0.038167274
B9: Other Expenses | C9: ='Finacial Anaylsis'!C12/'Finacial Anaylsis'!C$7 -> 0.13985657 | D9: ='Finacial Anaylsis'!D12/'Finacial Anaylsis'!D$7 -> 0.1281927 | E9: ='Finacial Anaylsis'!E12/'Finacial Anaylsis'!E$7 -> 0.12524339 | F9: ='Finacial Anaylsis'!F12/'Finacial Anaylsis'!F$7 -> 0.13522369
B10: TOTAL | C10: ='Finacial Anaylsis'!C13/'Finacial Anaylsis'!C$7 -> 0.84669815 | D10: ='Finacial Anaylsis'!D13/'Finacial Anaylsis'!D$7 -> 0.8493868 | E10: ='Finacial Anaylsis'!E13/'Finacial Anaylsis'!E$7 -> 0.85008909 | F10: ='Finacial Anaylsis'!F13/'Finacial Anaylsis'!F$7 -> 0.87357628
B11: EBITDA | C11: ='Finacial Anaylsis'!C14/'Finacial Anaylsis'!C$7 -> 0.15330185 | D11: ='Finacial Anaylsis'!D14/'Finacial Anaylsis'!D$7 -> 0.1506132 | E11: ='Finacial Anaylsis'!E14/'Finacial Anaylsis'!E$7 -> 0.14991091 | F11: ='Finacial Anaylsis'!F14/'Finacial Anaylsis'!F$7 -> 0.12642372
B12: Depreciation & Amortization | C12: ='Finacial Anaylsis'!C15/'Finacial Anaylsis'!C$7 -> 0.048998941 | D12: ='Finacial Anaylsis'!D15/'Finacial Anaylsis'!D$7 -> 0.038244841 | E12: ='Finacial Anaylsis'!E15/'Finacial Anaylsis'!E$7 -> 0.034579887 | F12: ='Finacial Anaylsis'!F15/'Finacial Anaylsis'!F$7 -> 0.035097626
B13: EBIT | C13: ='Finacial Anaylsis'!C16/'Finacial Anaylsis'!C$7 -> 0.10430291 | D13: ='Finacial Anaylsis'!D16/'Finacial Anaylsis'!D$7 -> 0.11236836 | E13: ='Finacial Anaylsis'!E16/'Finacial Anaylsis'!E$7 -> 0.11533103 | F13: ='Finacial Anaylsis'!F16/'Finacial Anaylsis'!F$7 -> 0.091326095
B14: Interest | C14: ='Finacial Anaylsis'!C17/'Finacial Anaylsis'!C$7 -> 0.0014186737 | D14: ='Finacial Anaylsis'!D17/'Finacial Anaylsis'!D$7 -> 0.0013130646 | E14: ='Finacial Anaylsis'!E17/'Finacial Anaylsis'!E$7 -> 0.004332823 | F14: ='Finacial Anaylsis'!F17/'Finacial Anaylsis'!F$7 -> 0.00088185573
B15: Profit Before Taxes | C15: ='Finacial Anaylsis'!C18/'Finacial Anaylsis'!C$7 -> 0.128594 | D15: ='Finacial Anaylsis'!D18/'Finacial Anaylsis'!D$7 -> 0.14468385 | E15: ='Finacial Anaylsis'!E18/'Finacial Anaylsis'!E$7 -> 0.13663178 | F15: ='Finacial Anaylsis'!F18/'Finacial Anaylsis'!F$7 -> 0.12020658
... B17: Profit for the Year | C17: ='Finacial Anaylsis'!C20/'Finacial Anaylsis'!C$7 -> 0.09234576 | D17: ='Finacial Anaylsis'!D20/'Finacial Anaylsis'!D$7 -> 0.10625835 | E17: ='Finacial Anaylsis'!E20/'Finacial Anaylsis'!E$7 -> 0.095456174 | F17: ='Finacial Anaylsis'!F20/'Finacial Anaylsis'!F$7 -> 0.085662002
B19: Balance sheet | C19: 2022A | D19: 2023A | E19: 2024A | F19: 2025A
B20: Shareholder Funds
B21: Share Capital | C21: =IF('Finacial Anaylsis'!C25/'Finacial Anaylsis'!C$40=0," ",'Finacial Anaylsis'!C25/'Finacial Anaylsis'!C$40) -> 0.0035341892 | D21: =IF('Finacial Anaylsis'!D25/'Finacial Anaylsis'!D$40=0," ",'Finacial Anaylsis'!D25/'Finacial Anaylsis'!D$40) -> 0.0029060536 | E21: =IF('Finacial Anaylsis'!E25/'Finacial Anaylsis'!E$40=0," ",'Finacial Anaylsis'!E25/'Finacial Anaylsis'!E$40) -> 0.0025062906 | F21: =IF('Finacial Anaylsis'!F25/'Finacial Anaylsis'!F$40=0," ",'Finacial Anaylsis'!F25/'Finacial Anaylsis'!F$40) -> 0.0023605294
B22: Reserves & Surplus | C22: =IF('Finacial Anaylsis'!C26/'Finacial Anaylsis'!C$40=0," ",'Finacial Anaylsis'!C26/'Finacial Anaylsis'!C$40) -> 0.71304022 | D22: =IF('Finacial Anaylsis'!D26/'Finacial Anaylsis'!D$40=0," ",'Finacial Anaylsis'!D26/'Finacial Anaylsis'!D$40) -> 0.71061864 | E22: =IF('Finacial Anaylsis'!E26/'Finacial Anaylsis'!E$40=0," ",'Finacial Anaylsis'!E26/'Finacial Anaylsis'!E$40) -> 0.70389255 | F22: =IF('Finacial Anaylsis'!F26/'Finacial Anaylsis'!F$40=0," ",'Finacial Anaylsis'!F26/'Finacial Anaylsis'!F$40) -> 0.73381357
B23: Minority Interest | C23: =IF('Finacial Anaylsis'!C27/'Finacial Anaylsis'!C$40=0," ",'Finacial Anaylsis'!C27/'Finacial Anaylsis'!C$40) -> 0.00033703526 | D23: =IF('Finacial Anaylsis'!D27/'Finacial Anaylsis'!D$40=0," ",'Finacial Anaylsis'!D27/'Finacial Anaylsis'!D$40) -> 0.00029637898 | E23: =IF('Finacial Anaylsis'!E27/'Finacial Anaylsis'!E$40=0," ",'Finacial Anaylsis'!E27/'Finacial Anaylsis'!E$40) -> 0.00026722701 | F23: =IF('Finacial Anaylsis'!F27/'Finacial Anaylsis'!F$40=0," ",'Finacial Anaylsis'!F27/'Finacial Anaylsis'!F$40) -> 0.00027513456
B24: Long Term Liabilities | C24: =IF('Finacial Anaylsis'!C28/'Finacial Anaylsis'!C$40=0," ",'Finacial Anaylsis'!C28/'Finacial Anaylsis'!C$40) | D24: =IF('Finacial Anaylsis'!D28/'Finacial Anaylsis'!D$40=0," ",'Finacial Anaylsis'!D28/'Finacial Anaylsis'!D$40) | E24: =IF('Finacial Anaylsis'!E28/'Finacial Anaylsis'!E$40=0," ",'Finacial Anaylsis'!E28/'Finacial Anaylsis'!E$40) | F24: =IF('Finacial Anaylsis'!F28/'Finacial Anaylsis'!F$40=0," ",'Finacial Anaylsis'!F28/'Finacial Anaylsis'!F$40)
B25: Loans | C25: =IF('Finacial Anaylsis'!C29/'Finacial Anaylsis'!C$40=0," ",'Finacial Anaylsis'!C29/'Finacial Anaylsis'!C$40) | D25: =IF('Finacial Anaylsis'!D29/'Finacial Anaylsis'!D$40=0," ",'Finacial Anaylsis'!D29/'Finacial Anaylsis'!D$40) | E25: =IF('Finacial Anaylsis'!E29/'Finacial Anaylsis'!E$40=0," ",'Finacial Anaylsis'!E29/'Finacial Anaylsis'!E$40) -> 0.00016597951 | F25: =IF('Finacial Anaylsis'!F29/'Finacial Anaylsis'!F$40=0," ",'Finacial Anaylsis'!F29/'Finacial Anaylsis'!F$40) -> 0.00012506116
B26: Other Long Term Liabilities | C26: =IF('Finacial Anaylsis'!C30/'Finacial Anaylsis'!C$40=0," ",'Finacial Anaylsis'!C30/'Finacial Anaylsis'!C$40) -> 0.01889972 | D26: =IF('Finacial Anaylsis'!D30/'Finacial Anaylsis'!D$40=0," ",'Finacial Anaylsis'!D30/'Finacial Anaylsis'!D$40) -> 0.021275777 | E26: =IF('Finacial Anaylsis'!E30/'Finacial Anaylsis'!E$40=0," ",'Finacial Anaylsis'!E30/'Finacial Anaylsis'!E$40) -> 0.026322691 | F26: =IF('Finacial Anaylsis'!F30/'Finacial Anaylsis'!F$40=0," ",'Finacial Anaylsis'!F30/'Finacial Anaylsis'!F$40) -> 0.031845262
B27: Long Term Provisions | C27: =IF('Finacial Anaylsis'!C31/'Finacial Anaylsis'!C$40=0," ",'Finacial Anaylsis'!C31/'Finacial Anaylsis'!C$40) -> 0.00034639735 | D27: =IF('Finacial Anaylsis'!D31/'Finacial Anaylsis'!D$40=0," ",'Finacial Anaylsis'!D31/'Finacial Anaylsis'!D$40) -> 0.000421474 | E27: =IF('Finacial Anaylsis'!E31/'Finacial Anaylsis'!E$40=0," ",'Finacial Anaylsis'!E31/'Finacial Anaylsis'!E$40) -> 0.00043984571 | F27: =IF('Finacial Anaylsis'!F31/'Finacial Anaylsis'!F$40=0," ",'Finacial Anaylsis'!F31/'Finacial Anaylsis'!F$40) -> 0.00061748949
B28: Deferred Tax Liabilities | C28: =IF('Finacial Anaylsis'!C32/'Finacial Anaylsis'!C$40=0," ",'Finacial Anaylsis'!C32/'Finacial Anaylsis'!C$40) -> 0.0053527753 | D28: =IF('Finacial Anaylsis'!D32/'Finacial Anaylsis'!D$40=0," ",'Finacial Anaylsis'!D32/'Finacial Anaylsis'!D$40) -> 0.0097343174 | E28: =IF('Finacial Anaylsis'!E32/'Finacial Anaylsis'!E$40=0," ",'Finacial Anaylsis'!E32/'Finacial Anaylsis'!E$40) -> 0.0099919666 | F28: =IF('Finacial Anaylsis'!F32/'Finacial Anaylsis'!F$40=0," ",'Finacial Anaylsis'!F32/'Finacial Anaylsis'!F$40) -> 0.009596881
B29: Current Liabilities | C29: =IF('Finacial Anaylsis'!C33/'Finacial Anaylsis'!C$40=0," ",'Finacial Anaylsis'!C33/'Finacial Anaylsis'!C$40) | D29: =IF('Finacial Anaylsis'!D33/'Finacial Anaylsis'!D$40=0," ",'Finacial Anaylsis'!D33/'Finacial Anaylsis'!D$40) | E29: =IF('Finacial Anaylsis'!E33/'Finacial Anaylsis'!E$40=0," ",'Finacial Anaylsis'!E33/'Finacial Anaylsis'!E$40) | F29: =IF('Finacial Anaylsis'!F33/'Finacial Anaylsis'!F$40=0," ",'Finacial Anaylsis'!F33/'Finacial Anaylsis'!F$40)
B30: Tax Liabilities | C30: =IF('Finacial Anaylsis'!C34/'Finacial Anaylsis'!C$40=0," ",'Finacial Anaylsis'!C34/'Finacial Anaylsis'!C$40) -> 0.018621198 | D30: =IF('Finacial Anaylsis'!D34/'Finacial Anaylsis'!D$40=0," ",'Finacial Anaylsis'!D34/'Finacial Anaylsis'!D$40) -> 0.015465594 | E30: =IF('Finacial Anaylsis'!E34/'Finacial Anaylsis'!E$40=0," ",'Finacial Anaylsis'!E34/'Finacial Anaylsis'!E$40) -> 0.01417631 | F30: =IF('Finacial Anaylsis'!F34/'Finacial Anaylsis'!F$40=0," ",'Finacial Anaylsis'!F34/'Finacial Anaylsis'!F$40) -> 0.010519207
B31: Short Term Borrowings | C31: =IF('Finacial Anaylsis'!C35/'Finacial Anaylsis'!C$40=0," ",'Finacial Anaylsis'!C35/'Finacial Anaylsis'!C$40) -> 0.0018115645 | D31: =IF('Finacial Anaylsis'!D35/'Finacial Anaylsis'!D$40=0," ",'Finacial Anaylsis'!D35/'Finacial Anaylsis'!D$40) -> 0.0093070698 | E31: =IF('Finacial Anaylsis'!E35/'Finacial Anaylsis'!E$40=0," ",'Finacial Anaylsis'!E35/'Finacial Anaylsis'!E$40) -> 0.001839053 | F31: =IF('Finacial Anaylsis'!F35/'Finacial Anaylsis'!F$40=0," ",'Finacial Anaylsis'!F35/'Finacial Anaylsis'!F$40) -> 0.0023386437
B32: Trade Payables | C32: =IF('Finacial Anaylsis'!C36/'Finacial Anaylsis'!C$40=0," ",'Finacial Anaylsis'!C36/'Finacial Anaylsis'!C$40) -> 0.17340698 | D32: =IF('Finacial Anaylsis'!D36/'Finacial Anaylsis'!D$40=0," ",'Finacial Anaylsis'!D36/'Finacial Anaylsis'!D$40) -> 0.1610685 | E32: =IF('Finacial Anaylsis'!E36/'Finacial Anaylsis'!E$40=0," ",'Finacial Anaylsis'!E36/'Finacial Anaylsis'!E$40) -> 0.17426687 | F32: =IF('Finacial Anaylsis'!F36/'Finacial Anaylsis'!F$40=0," ",'Finacial Anaylsis'!F36/'Finacial Anaylsis'!F$40) -> 0.15066275
... B36: TOTAL | C36: =IF('Finacial Anaylsis'!C40/'Finacial Anaylsis'!C$40=0," ",'Finacial Anaylsis'!C40/'Finacial Anaylsis'!C$40) -> 1 | D36: =IF('Finacial Anaylsis'!D40/'Finacial Anaylsis'!D$40=0," ",'Finacial Anaylsis'!D40/'Finacial Anaylsis'!D$40) -> 1 | E36: =IF('Finacial Anaylsis'!E40/'Finacial Anaylsis'!E$40=0," ",'Finacial Anaylsis'!E40/'Finacial Anaylsis'!E$40) -> 1 | F36: =IF('Finacial Anaylsis'!F40/'Finacial Anaylsis'!F$40=0," ",'Finacial Anaylsis'!F40/'Finacial Anaylsis'!F$40) -> 1
B37: APPLICATION OF FUNDS
B38: Long Term Assets
B39: Tangible Assets | C39: =IF('Finacial Anaylsis'!C43/'Finacial Anaylsis'!C$40=0," ",'Finacial Anaylsis'!C43/'Finacial Anaylsis'!C$40) -> 0.28513885 | D39: =IF('Finacial Anaylsis'!D43/'Finacial Anaylsis'!D$40=0," ",'Finacial Anaylsis'!D43/'Finacial Anaylsis'!D$40) -> 0.24899106 | E39: =IF('Finacial Anaylsis'!E43/'Finacial Anaylsis'!E$40=0," ",'Finacial Anaylsis'!E43/'Finacial Anaylsis'!E$40) -> 0.21705307 | F39: =IF('Finacial Anaylsis'!F43/'Finacial Anaylsis'!F$40=0," ",'Finacial Anaylsis'!F43/'Finacial Anaylsis'!F$40) -> 0.23427395
B40: Intangible Assets | C40: =IF('Finacial Anaylsis'!C44/'Finacial Anaylsis'!C$40=0," ",'Finacial Anaylsis'!C44/'Finacial Anaylsis'!C$40) -> 0.008119273 | D40: =IF('Finacial Anaylsis'!D44/'Finacial Anaylsis'!D$40=0," ",'Finacial Anaylsis'!D44/'Finacial Anaylsis'!D$40) -> 0.0071785298 | E40: =IF('Finacial Anaylsis'!E44/'Finacial Anaylsis'!E$40=0," ",'Finacial Anaylsis'!E44/'Finacial Anaylsis'!E$40) -> 0.0051735814 | F40: =IF('Finacial Anaylsis'!F44/'Finacial Anaylsis'!F$40=0," ",'Finacial Anaylsis'!F44/'Finacial Anaylsis'!F$40) -> 0.0070518863
B41: Capital Work in Progress | C41: =IF('Finacial Anaylsis'!C45/'Finacial Anaylsis'!C$40=0," ",'Finacial Anaylsis'!C45/'Finacial Anaylsis'!C$40) -> 0.023566722 | D41: =IF('Finacial Anaylsis'!D45/'Finacial Anaylsis'!D$40=0," ",'Finacial Anaylsis'!D45/'Finacial Anaylsis'!D$40) -> 0.024101 | E41: =IF('Finacial Anaylsis'!E45/'Finacial Anaylsis'!E$40=0," ",'Finacial Anaylsis'!E45/'Finacial Anaylsis'!E$40) -> 0.035388492 | F41: =IF('Finacial Anaylsis'!F45/'Finacial Anaylsis'!F$40=0," ",'Finacial Anaylsis'!F45/'Finacial Anaylsis'!F$40) -> 0.025120098
B42: Non-Current Investments | C42: =IF('Finacial Anaylsis'!C46/'Finacial Anaylsis'!C$40=0," ",'Finacial Anaylsis'!C46/'Finacial Anaylsis'!C$40) -> 0.45720939 | D42: =IF('Finacial Anaylsis'!D46/'Finacial Anaylsis'!D$40=0," ",'Finacial Anaylsis'!D46/'Finacial Anaylsis'!D$40) -> 0.51908276 | E42: =IF('Finacial Anaylsis'!E46/'Finacial Anaylsis'!E$40=0," ",'Finacial Anaylsis'!E46/'Finacial Anaylsis'!E$40) -> 0.57936476 | F42: =IF('Finacial Anaylsis'!F46/'Finacial Anaylsis'!F$40=0," ",'Finacial Anaylsis'!F46/'Finacial Anaylsis'!F$40) -> 0.50740597
B43: Other Financial Assets | C43: =IF('Finacial Anaylsis'!C47/'Finacial Anaylsis'!C$40=0," ",'Finacial Anaylsis'!C47/'Finacial Anaylsis'!C$40) -> 0.0005476823 | D43: =IF('Finacial Anaylsis'!D47/'Finacial Anaylsis'!D$40=0," ",'Finacial Anaylsis'!D47/'Finacial Anaylsis'!D$40) -> 0.00046381386 | E43: =IF('Finacial Anaylsis'!E47/'Finacial Anaylsis'!E$40=0," ",'Finacial Anaylsis'!E47/'Finacial Anaylsis'!E$40) -> 0.0005444128 | F43: =IF('Finacial Anaylsis'!F47/'Finacial Anaylsis'!F$40=0," ",'Finacial Anaylsis'!F47/'Finacial Anaylsis'!F$40) -> 0.000537763
B44: Long Term Loans and Advances | C44: =IF('Finacial Anaylsis'!C48/'Finacial Anaylsis'!C$40=0," ",'Finacial Anaylsis'!C48/'Finacial Anaylsis'!C$40) -> 9.3620906e-06 | D44: =IF('Finacial Anaylsis'!D48/'Finacial Anaylsis'!D$40=0," ",'Finacial Anaylsis'!D48/'Finacial Anaylsis'!D$40) -> 5.7736165e-06 | E44: =IF('Finacial Anaylsis'!E48/'Finacial Anaylsis'!E$40=0," ",'Finacial Anaylsis'!E48/'Finacial Anaylsis'!E$40) -> 3.3195902e-06 | F44: =IF('Finacial Anaylsis'!F48/'Finacial Anaylsis'!F$40=0," ",'Finacial Anaylsis'!F48/'Finacial Anaylsis'!F$40) -> 3.1265291e-06
B45: Other Non Current Assets | C45: =IF('Finacial Anaylsis'!C49/'Finacial Anaylsis'!C$40=0," ",'Finacial Anaylsis'!C49/'Finacial Anaylsis'!C$40) -> 0.039311418 | D45: =IF('Finacial Anaylsis'!D49/'Finacial Anaylsis'!D$40=0," ",'Finacial Anaylsis'!D49/'Finacial Anaylsis'!D$40) -> 0.030856131 | E45: =IF('Finacial Anaylsis'!E49/'Finacial Anaylsis'!E$40=0," ",'Finacial Anaylsis'!E49/'Finacial Anaylsis'!E$40) -> 0.030850612 | F45: =IF('Finacial Anaylsis'!F49/'Finacial Anaylsis'!F$40=0," ",'Finacial Anaylsis'!F49/'Finacial Anaylsis'!F$40) -> 0.03218918
B46: Current Assets | C46: =IF('Finacial Anaylsis'!C50/'Finacial Anaylsis'!C$40=0," ",'Finacial Anaylsis'!C50/'Finacial Anaylsis'!C$40) | D46: =IF('Finacial Anaylsis'!D50/'Finacial Anaylsis'!D$40=0," ",'Finacial Anaylsis'!D50/'Finacial Anaylsis'!D$40) | E46: =IF('Finacial Anaylsis'!E50/'Finacial Anaylsis'!E$40=0," ",'Finacial Anaylsis'!E50/'Finacial Anaylsis'!E$40) | F46: =IF('Finacial Anaylsis'!F50/'Finacial Anaylsis'!F$40=0," ",'Finacial Anaylsis'!F50/'Finacial Anaylsis'!F$40)
B47: Inventories | C47: =IF('Finacial Anaylsis'!C51/'Finacial Anaylsis'!C$40=0," ",'Finacial Anaylsis'!C51/'Finacial Anaylsis'!C$40) -> 0.073319212 | D47: =IF('Finacial Anaylsis'!D51/'Finacial Anaylsis'!D$40=0," ",'Finacial Anaylsis'!D51/'Finacial Anaylsis'!D$40) -> 0.062811174 | E47: =IF('Finacial Anaylsis'!E51/'Finacial Anaylsis'!E$40=0," ",'Finacial Anaylsis'!E51/'Finacial Anaylsis'!E$40) -> 0.052452845 | F47: =IF('Finacial Anaylsis'!F51/'Finacial Anaylsis'!F$40=0," ",'Finacial Anaylsis'!F51/'Finacial Anaylsis'!F$40) -> 0.051941027
...

Sheet Horizontal anaylsis
B2: Horizontal Analysis | C2: 2022A | D2: 2023A | E2: 2024A | F2: 2025A
B3: Revenue from operations | D3: ='Finacial Anaylsis'!D7/'Finacial Anaylsis'!C7-1 -> 0.18225703 | E3: ='Finacial Anaylsis'!E7/'Finacial Anaylsis'!D7-1 -> 0.17220239 | F3: ='Finacial Anaylsis'!F7/'Finacial Anaylsis'!E7-1 -> 0.078425599
B4: Other Income | D4: ='Finacial Anaylsis'!D8/'Finacial Anaylsis'!C8-1 -> 0.54640011 | E4: ='Finacial Anaylsis'!E8/'Finacial Anaylsis'!D8-1 -> -0.10648148 | F4: ='Finacial Anaylsis'!F8/'Finacial Anaylsis'!E8-1 -> 0.25212631
B5: TOTAL | D5: ='Finacial Anaylsis'!D9/'Finacial Anaylsis'!C9-1 -> 0.1913844 | E5: ='Finacial Anaylsis'!E9/'Finacial Anaylsis'!D9-1 -> 0.16313556 | F5: ='Finacial Anaylsis'!F9/'Finacial Anaylsis'!E9-1 -> 0.082766886
B6: Raw Materials | D6: ='Finacial Anaylsis'!D10/'Finacial Anaylsis'!C10-1 -> 0.20762156 | E6: ='Finacial Anaylsis'!E10/'Finacial Anaylsis'!D10-1 -> 0.17636953 | F6: ='Finacial Anaylsis'!F10/'Finacial Anaylsis'!E10-1 -> 0.095984258
B7: Employee Cost | D7: ='Finacial Anaylsis'!D11/'Finacial Anaylsis'!C11-1 -> 0.179973 | E7: ='Finacial Anaylsis'!E11/'Finacial Anaylsis'!D11-1 -> 0.21315087 | F7: ='Finacial Anaylsis'!F11/'Finacial Anaylsis'!E11-1 -> 0.14723755
B8: Other Expenses | D8: ='Finacial Anaylsis'!D12/'Finacial Anaylsis'!C12-1 -> 0.083658216 | E8: ='Finacial Anaylsis'!E12/'Finacial Anaylsis'!D12-1 -> 0.14523373 | F8: ='Finacial Anaylsis'!F12/'Finacial Anaylsis'!E12-1 -> 0.16436232
B9: TOTAL | D9: ='Finacial Anaylsis'!D13/'Finacial Anaylsis'!C13-1 -> 0.18601122 | E9: ='Finacial Anaylsis'!E13/'Finacial Anaylsis'!D13-1 -> 0.1731716 | F9: ='Finacial Anaylsis'!F13/'Finacial Anaylsis'!E13-1 -> 0.10822152
B10: EBITDA | D10: ='Finacial Anaylsis'!D14/'Finacial Anaylsis'!C14-1 -> 0.16152234 | E10: ='Finacial Anaylsis'!E14/'Finacial Anaylsis'!D14-1 -> 0.16673655 | F10: ='Finacial Anaylsis'!F14/'Finacial Anaylsis'!E14-1 -> -0.090536011
B11: Depreciation & Amortization | D11: ='Finacial Anaylsis'!D15/'Finacial Anaylsis'!C15-1 -> -0.077220214 | E11: ='Finacial Anaylsis'!E15/'Finacial Anaylsis'!D15-1 -> 0.059871731 | F11: ='Finacial Anaylsis'!F15/'Finacial Anaylsis'!E15-1 -> 0.09457207
B12: EBIT | D12: ='Finacial Anaylsis'!D16/'Finacial Anaylsis'!C16-1 -> 0.27367773 | E12: ='Finacial Anaylsis'!E16/'Finacial Anaylsis'!D16-1 -> 0.20310825 | F12: ='Finacial Anaylsis'!F16/'Finacial Anaylsis'!E16-1 -> -0.14603726
B13: Interest | D13: ='Finacial Anaylsis'!D17/'Finacial Anaylsis'!C17-1 -> 0.094247246 | E13: ='Finacial Anaylsis'!E17/'Finacial Anaylsis'!D17-1 -> 2.8680089 | F13: ='Finacial Anaylsis'!F17/'Finacial Anaylsis'!E17-1 -> -0.78050896
B14: Profit Before Taxes | D14: ='Finacial Anaylsis'!D18/'Finacial Anaylsis'!C18-1 -> 0.33018256 | E14: ='Finacial Anaylsis'!E18/'Finacial Anaylsis'!D18-1 -> 0.10696593 | F14: ='Finacial Anaylsis'!F18/'Finacial Anaylsis'!E18-1 -> -0.051217387
... B16: Profit for the Year | D16: ='Finacial Anaylsis'!D20/'Finacial Anaylsis'!C20-1 -> 0.36037307 | E16: ='Finacial Anaylsis'!E20/'Finacial Anaylsis'!D20-1 -> 0.053036795 | F16: ='Finacial Anaylsis'!F20/'Finacial Anaylsis'!E20-1 -> -0.032225037
B18: Balance sheet | C18: 2022A | D18: 2023A | E18: 2024A | F18: 2025A
B19: Shareholder Funds
B20: Share Capital | D20: =IFERROR('Finacial Anaylsis'!D25/'Finacial Anaylsis'!C25-1,"") -> 0 | E20: =IFERROR('Finacial Anaylsis'!E25/'Finacial Anaylsis'!D25-1,"") -> 0 | F20: =IFERROR('Finacial Anaylsis'!F25/'Finacial Anaylsis'!E25-1,"") -> 0
B21: Reserves & Surplus | D21: =IFERROR('Finacial Anaylsis'!D26/'Finacial Anaylsis'!C26-1,"") -> 0.21201707 | E21: =IFERROR('Finacial Anaylsis'!E26/'Finacial Anaylsis'!D26-1,"") -> 0.14852901 | F21: =IFERROR('Finacial Anaylsis'!F26/'Finacial Anaylsis'!E26-1,"") -> 0.10688213
B22: Minority Interest | D22: =IFERROR('Finacial Anaylsis'!D27/'Finacial Anaylsis'!C27-1,"") -> 0.069444444 | E22: =IFERROR('Finacial Anaylsis'!E27/'Finacial Anaylsis'!D27-1,"") -> 0.045454545 | F22: =IFERROR('Finacial Anaylsis'!F27/'Finacial Anaylsis'!E27-1,"") -> 0.093167702
B23: Long Term Liabilities | D23: =IFERROR('Finacial Anaylsis'!D28/'Finacial Anaylsis'!C28-1,"") | E23: =IFERROR('Finacial Anaylsis'!E28/'Finacial Anaylsis'!D28-1,"") | F23: =IFERROR('Finacial Anaylsis'!F28/'Finacial Anaylsis'!E28-1,"")
B24: Loans | D24: =IFERROR('Finacial Anaylsis'!D29/'Finacial Anaylsis'!C29-1,"") | E24: =IFERROR('Finacial Anaylsis'!E29/'Finacial Anaylsis'!D29-1,"") | F24: =IFERROR('Finacial Anaylsis'!F29/'Finacial Anaylsis'!E29-1,"") -> -0.2
B25: Other Long Term Liabilities | D25: =IFERROR('Finacial Anaylsis'!D30/'Finacial Anaylsis'!C30-1,"") -> 0.36904025 | E25: =IFERROR('Finacial Anaylsis'!E30/'Finacial Anaylsis'!D30-1,"") -> 0.4345545 | F25: =IFERROR('Finacial Anaylsis'!F30/'Finacial Anaylsis'!E30-1,"") -> 0.28450722
B26: Long Term Provisions | D26: =IFERROR('Finacial Anaylsis'!D31/'Finacial Anaylsis'!C31-1,"") -> 0.47972973 | E26: =IFERROR('Finacial Anaylsis'!E31/'Finacial Anaylsis'!D31-1,"") -> 0.21004566 | F26: =IFERROR('Finacial Anaylsis'!F31/'Finacial Anaylsis'!E31-1,"") -> 0.49056604
B27: Deferred Tax Liabilities | D27: =IFERROR('Finacial Anaylsis'!D32/'Finacial Anaylsis'!C32-1,"") -> 1.211631 | E27: =IFERROR('Finacial Anaylsis'!E32/'Finacial Anaylsis'!D32-1,"") -> 0.19019375 | F27: =IFERROR('Finacial Anaylsis'!F32/'Finacial Anaylsis'!E32-1,"") -> 0.019767442
B28: Current Liabilities | D28: =IFERROR('Finacial Anaylsis'!D33/'Finacial Anaylsis'!C33-1,"") | E28: =IFERROR('Finacial Anaylsis'!E33/'Finacial Anaylsis'!D33-1,"") | F28: =IFERROR('Finacial Anaylsis'!F33/'Finacial Anaylsis'!E33-1,"")
B29: Tax Liabilities | D29: =IFERROR('Finacial Anaylsis'!D34/'Finacial Anaylsis'!C34-1,"") -> 0.010055304 | E29: =IFERROR('Finacial Anaylsis'!E34/'Finacial Anaylsis'!D34-1,"") -> 0.06284221 | F29: =IFERROR('Finacial Anaylsis'!F34/'Finacial Anaylsis'!E34-1,"") -> -0.21215314
B30: Short Term Borrowings | D30: =IFERROR('Finacial Anaylsis'!D35/'Finacial Anaylsis'!C35-1,"") -> 5.248062 | E30: =IFERROR('Finacial Anaylsis'!E35/'Finacial Anaylsis'!D35-1,"") -> -0.77088503 | F30: =IFERROR('Finacial Anaylsis'!F35/'Finacial Anaylsis'!E35-1,"") -> 0.35018051
B31: Trade Payables | D31: =IFERROR('Finacial Anaylsis'!D36/'Finacial Anaylsis'!C36-1,"") -> 0.12961438 | E31: =IFERROR('Finacial Anaylsis'!E36/'Finacial Anaylsis'!D36-1,"") -> 0.25451656 | F31: =IFERROR('Finacial Anaylsis'!F36/'Finacial Anaylsis'!E36-1,"") -> -0.082062614
... B54: TOTAL | D54: =IFERROR('Finacial Anaylsis'!D59/'Finacial Anaylsis'!C59-1,"") -> 0.21614727 | E54: =IFERROR('Finacial Anaylsis'!E59/'Finacial Anaylsis'!D59-1,"") -> 0.15950385 | F54: =IFERROR('Finacial Anaylsis'!F59/'Finacial Anaylsis'!E59-1,"") -> 0.061749358

Sheet Ratio Anaylsis
B2: RATIO ANALYSIS | C2: 2022A | D2: 2023A | E2: 2024A | F2: 2025A
B3: Growth Ratio
B4: Revenue growth % (y-o-y) | D4: ='Horizontal anaylsis'!D3 -> 0.18225703 | E4: ='Horizontal anaylsis'!E3 -> 0.17220239 | F4: ='Horizontal anaylsis'!F3 -> 0.078425599
B5: Earnings growth % | D5: ='Horizontal anaylsis'!D16 -> 0.36037307 | E5: ='Horizontal anaylsis'!E16 -> 0.053036795 | F5: ='Horizontal anaylsis'!F16 -> -0.032225037
B6: Profitability Ratio
B7: GP% | C7: =('Finacial Anaylsis'!C7-'Finacial Anaylsis'!C10)/'Finacial Anaylsis'!C7 -> 0.32789248 | D7: =('Finacial Anaylsis'!D7-'Finacial Anaylsis'!D10)/'Finacial Anaylsis'!D7 -> 0.31347286 | E7: =('Finacial Anaylsis'!E7-'Finacial Anaylsis'!E10)/'Finacial Anaylsis'!E7 -> 0.31103228 | F7: =('Finacial Anaylsis'!F7-'Finacial Anaylsis'!F10)/'Finacial Anaylsis'!F7 -> 0.29981468
B8: EBITDA% | C8: ='Vertical Anaylsis'!C11 -> 0.15330185 | D8: ='Vertical Anaylsis'!D11 -> 0.1506132 | E8: ='Vertical Anaylsis'!E11 -> 0.14991091 | F8: ='Vertical Anaylsis'!F11 -> 0.12642372
B9: EBIT % | C9: ='Vertical Anaylsis'!C13 -> 0.10430291 | D9: ='Vertical Anaylsis'!D13 -> 0.11236836 | E9: ='Vertical Anaylsis'!E13 -> 0.11533103 | F9: ='Vertical Anaylsis'!F13 -> 0.091326095
B10: NP % | C10: ='Vertical Anaylsis'!C17 -> 0.09234576 | D10: ='Vertical Anaylsis'!D17 -> 0.10625835 | E10: ='Vertical Anaylsis'!E17 -> 0.095456174 | F10: ='Vertical Anaylsis'!F17 -> 0.085662002
B11: ROA | C11: ='Finacial Anaylsis'!C20/AVERAGE('Finacial Anaylsis'!C40) -> 0.12447133 | D11: ='Finacial Anaylsis'!D20/AVERAGE('Finacial Anaylsis'!D40) -> 0.13923269 | E11: ='Finacial Anaylsis'!E20/AVERAGE('Finacial Anaylsis'!E40) -> 0.12644817 | F11: ='Finacial Anaylsis'!F20/AVERAGE('Finacial Anaylsis'!F40) -> 0.11525637
B12: ROE | C12: ='Finacial Anaylsis'!C20/AVERAGE('Finacial Anaylsis'!C24) -> 0.17362163 | D12: ='Finacial Anaylsis'!D20/AVERAGE('Finacial Anaylsis'!D24) -> 0.19505264 | E12: ='Finacial Anaylsis'!E20/AVERAGE('Finacial Anaylsis'!E24) -> 0.17893624 | F12: ='Finacial Anaylsis'!F20/AVERAGE('Finacial Anaylsis'!F24) -> 0.1565028
B13: Efficiency Ratio
B14: Asset Turnover | C14: ='Finacial Anaylsis'!C7/AVERAGE('Finacial Anaylsis'!C40) -> 1.3478836 | D14: ='Finacial Anaylsis'!D7/AVERAGE('Finacial Anaylsis'!D40) -> 1.3103223 | E14: ='Finacial Anaylsis'!E7/AVERAGE('Finacial Anaylsis'!E40) -> 1.3246725 | F14: ='Finacial Anaylsis'!F7/AVERAGE('Finacial Anaylsis'!F40) -> 1.3454783
B15: Inventory Turnover | C15: ='Finacial Anaylsis'!C10/AVERAGE('Finacial Anaylsis'!C51) -> 12.355871 | D15: ='Finacial Anaylsis'!D10/AVERAGE('Finacial Anaylsis'!D51) -> 14.321843 | E15: ='Finacial Anaylsis'!E10/AVERAGE('Finacial Anaylsis'!E51) -> 17.399563 | F15: ='Finacial Anaylsis'!F10/AVERAGE('Finacial Anaylsis'!F51) -> 18.137573
B16: Receivable Turnover | C16: ='Finacial Anaylsis'!C7/AVERAGE('Finacial Anaylsis'!C52) -> 43.515944 | D16: ='Finacial Anaylsis'!D7/AVERAGE('Finacial Anaylsis'!D52) -> 56.614835 | E16: ='Finacial Anaylsis'!E7/AVERAGE('Finacial Anaylsis'!E52) -> 54.462536 | F16: ='Finacial Anaylsis'!F7/AVERAGE('Finacial Anaylsis'!F52) -> 37.213983
B17: Payable Turnover | C17: ='Finacial Anaylsis'!C10/AVERAGE('Finacial Anaylsis'!C36) -> 5.2242573 | D17: ='Finacial Anaylsis'!D10/AVERAGE('Finacial Anaylsis'!D36) -> 5.585026 | E17: ='Finacial Anaylsis'!E10/AVERAGE('Finacial Anaylsis'!E36) -> 5.2371206 | F17: ='Finacial Anaylsis'!F10/AVERAGE('Finacial Anaylsis'!F36) -> 6.2529338
B18: Liquidity Ratio
B19: Quick ratio | C19: =SUM('Finacial Anaylsis'!C52:C53,'Finacial Anaylsis'!C57)/SUM('Finacial Anaylsis'!C34:C39) -> 0.22775962 | D19: =SUM('Finacial Anaylsis'!D52:D53,'Finacial Anaylsis'!D57)/SUM('Finacial Anaylsis'!D34:D39) -> 0.25722984 | E19: =SUM('Finacial Anaylsis'!E52:E53,'Finacial Anaylsis'!E57)/SUM('Finacial Anaylsis'!E34:E39) -> 0.17844451 | F19: =SUM('Finacial Anaylsis'!F52:F53,'Finacial Anaylsis'!F57)/SUM('Finacial Anaylsis'!F34:F39) -> 0.53289785
B20: Current ratio | C20: =SUM('Finacial Anaylsis'!C51:C58)/SUM('Finacial Anaylsis'!C34:C39) -> 0.71994096 | D20: =SUM('Finacial Anaylsis'!D51:D58)/SUM('Finacial Anaylsis'!D34:D39) -> 0.66466215 | E20: =SUM('Finacial Anaylsis'!E51:E58)/SUM('Finacial Anaylsis'!E34:E39) -> 0.51331845 | F20: =SUM('Finacial Anaylsis'!F51:F58)/SUM('Finacial Anaylsis'!F34:F39) -> 0.8737474
B21: Cash Ratio
B22: Leverage Ratio
B23: Debt ratio | C23: ='Finacial Anaylsis'!C40/'Finacial Anaylsis'!C24 -> 1.3948724 | D23: ='Finacial Anaylsis'!D40/'Finacial Anaylsis'!D24 -> 1.4009113 | E23: ='Finacial Anaylsis'!E40/'Finacial Anaylsis'!E24 -> 1.4150955 | F23: ='Finacial Anaylsis'!F40/'Finacial Anaylsis'!F24 -> 1.3578669
B24: Debt-equity | C24: ='Finacial Anaylsis'!C29+'Finacial Anaylsis'!C35/'Finacial Anaylsis'!C24 -> 0.0025269014 | D24: ='Finacial Anaylsis'!D29+'Finacial Anaylsis'!D35/'Finacial Anaylsis'!D24 -> 0.013038379 | E24: ='Finacial Anaylsis'!E29+'Finacial Anaylsis'!E35/'Finacial Anaylsis'!E24 -> 100.0026 | F24: ='Finacial Anaylsis'!F29+'Finacial Anaylsis'!F35/'Finacial Anaylsis'!F24 -> 80.003176
B25: Interest Coverage | C25: ='Finacial Anaylsis'!C16/'Finacial Anaylsis'!C17 -> 73.52142 | D25: ='Finacial Anaylsis'!D16/'Finacial Anaylsis'!D17 -> 85.577181 | E25: ='Finacial Anaylsis'!E16/'Finacial Anaylsis'!E17 -> 26.617987 | F25: ='Finacial Anaylsis'!F16/'Finacial Anaylsis'!F17 -> 103.56126
